Workbook

Sheet Recieving
A1: DATE | B1: LUMPS INSIDE | C1: LUMPS OUTSIDE | D1: FINES INSIDE | E1: FINES OUTSIDE | F1: PELLETS | G1: SCRAP | H1: SM /PM / R. Scrap | I1: PIG IRON SPLASHES | J1: CI Mix Scrap | K1: GRANULES OF PIG IRON | L1: PIG IRON | M1: CI SKULL | N1: MS Scrap | O1: SLAG IRON Mag | P1: Over Size MAG | Q1: TOTAL | R1: BILLET END CUT | S1: SLAG JAAM | T1: MILL SCAL | V1: Internal Lumps Fe(M) | W1: Outer Lumps Fe(M) | X1: Pillets Fe(M) | Y1: Internal Fines Fe(M) | Z1: Outer Fines Fe(M) | AB1: Shearing Machine | AD1: A/L -Power | AE1: Silicon magnese | AG1: Lumps Total Fe(M) | AH1: Pillets Total Fe(M) | AI1: Fines Total Fe(M)
Q2: RECIVED RAW MATRIALS | AB2: Running (Hr) | AC2: Production | AD2: P/Days | AE2: Received | AF2: Issue
A3: 46296 | B3: 0 | C3: 0 | D3: 0 | E3: 0 | F3: 140.78 | G3: 246.45 | H3: 12.27 | I3: 0 | J3: 0.7 | K3: 0 | L3: 0 | M3: 0 | N3: 0 | O3: 33.41 | Q3: =SUM(B3:P3) -> 433.61 | R3: 5.37 | S3: 0 | T3: 0 | V3: 0 | W3: 0 | X3: 79.05 | Y3: 0 | Z3: 0 | AB3: 0.91666667 | AC3: 220 | AD3: 13 | AE3: 0 | AF3: 4800 | AG3: =(V3*B3)+(W3*C3) -> 0 | AH3: =F3*X3 -> 11128.659 | AI3: =(D3*Y3)+(E3*Z3) -> 0
A4: =+A3+1 -> 46297 | B4: 0 | C4: 0 | D4: 44.86 | E4: 0 | F4: 115.43 | G4: 182.31 | H4: 12.6 | I4: 0 | J4: 3.9 | K4: 0 | L4: 0 | M4: 0 | N4: 1.24 | O4: 0 | P4: 0 | Q4: =SUM(B4:P4) -> 360.34 | R4: 3.07 | S4: 9.53 | T4: 0 | V4: 0 | W4: 0 | X4: 79.26 | Y4: 77.06 | Z4: 0 | AB4: 0.75 | AC4: 180 | AD4: 13 | AE4: 0 | AF4: 5000 | AG4: =(V4*B4)+(W4*C4) -> 0 | AH4: =F4*X4 -> 9148.9818 | AI4: =(D4*Y4)+(E4*Z4) -> 3456.9116 | AJ4: Strip mill to SMS
A5: =+A4+1 -> 46298 | B5: 0 | C5: 0 | D5: 46.21 | E5: 0 | F5: 123.98 | G5: 218.62 | H5: 8.99 | I5: 0 | J5: 0.7 | K5: 0 | L5: 0 | M5: 0 | N5: 0 | O5: 0 | P5: 0 | Q5: =SUM(B5:P5) -> 398.5 | R5: 5.1 | S5: 7.35 | T5: 0 | V5: 0 | W5: 0 | X5: 78.46 | Y5: 76.54 | Z5: 0 | AB5: 0.79166667 | AC5: 190 | AD5: 13 | AE5: 0 | AF5: 5200 | AG5: =(V5*B5)+(W5*C5) -> 0 | AH5: =F5*X5 -> 9727.4708 | AI5: =(D5*Y5)+(E5*Z5) -> 3536.9134
A6: =+A5+1 -> 46299 | B6: 0 | C6: 0 | D6: 42.66 | E6: 49.48 | F6: 58.21 | G6: 295.09 | H6: 26.55 | I6: 0 | J6: 4 | K6: 0 | L6: 0 | M6: 0 | N6: 2.48 | O6: 0 | P6: 0 | Q6: =SUM(B6:P6) -> 478.47 | R6: 6.64 | S6: 3.86 | T6: 0 | V6: 0 | W6: 0 | X6: 78.89 | Y6: 76.46 | Z6: 69.58 | AB6: 0.83333333 | AC6: 200 | AD6: 13 | AE6: 0 | AF6: 5500 | AG6: =(V6*B6)+(W6*C6) -> 0 | AH6: =F6*X6 -> 4592.1869 | AI6: =(D6*Y6)+(E6*Z6) -> 6704.602 | AJ6: DRI to SMS
A7: =+A6+1 -> 46300 | B7: 0 | C7: 40.79 | D7: 47.84 | E7: 0 | F7: 124.35 | G7: 261.96 | H7: 14.22 | I7: 0 | J7: 0.5 | K7: 0 | L7: 0 | M7: 0 | N7: 0 | O7: 0 | P7: 0 | Q7: =SUM(B7:P7) -> 489.66 | R7: 6.05 | S7: 2.79 | T7: 0 | V7: 0 | W7: 78.59 | X7: 79.13 | Y7: 77.14 | Z7: 0 | AB7: 0.91666667 | AC7: 220 | AD7: 13 | AE7: 0 | AF7: 5200 | AG7: =(V7*B7)+(W7*C7) -> 3205.6861 | AH7: =F7*X7 -> 9839.8155 | AI7: =(D7*Y7)+(E7*Z7) -> 3690.3776
A8: =+A7+1 -> 46301 | B8: 0 | C8: 79.48 | D8: 47.99 | E8: 0 | F8: 120.48 | G8: 236.05 | H8: 14.74 | I8: 0 | J8: 0 | K8: 0 | L8: 0 | M8: 0 | N8: 0 | O8: 34.18 | P8: 0 | Q8: =SUM(B8:P8) -> 532.92 | R8: 6.07 | S8: 2.8 | T8: 0 | V8: 0 | W8: 76.45 | X8: 79.44 | Y8: 76.69 | Z8: 0 | AB8: 0.91666667 | AC8: 220 | AD8: 13 | AE8: 0 | AF8: 5000 | AG8: =(V8*B8)+(W8*C8) -> 6076.246 | AH8: =F8*X8 -> 9570.9312 | AI8: =(D8*Y8)+(E8*Z8) -> 3680.3531
A9: =+A8+1 -> 46302 | B9: 0 | C9: 0 | D9: 45.21 | E9: 0 | F9: 159.43 | G9: 282.83 | H9: 10.14 | I9: 0 | J9: 6.2 | K9: 0 | L9: 0 | M9: 0 | N9: 2.31 | O9: 0 | P9: 0 | Q9: =SUM(B9:P9) -> 506.12 | R9: 5.52 | S9: 0 | T9: 0 | V9: 0 | W9: 0 | X9: 79.38 | Y9: 77.03 | Z9: 0 | AB9: 0.91666667 | AC9: 220 | AD9: 13 | AE9: 0 | AF9: 5000 | AG9: =(V9*B9)+(W9*C9) -> 0 | AH9: =F9*X9 -> 12655.553 | AI9: =(D9*Y9)+(E9*Z9) -> 3482.5263 | AJ9: Dri to sms
A10: =+A9+1 -> 46303 | B10: 0 | C10: 122.77 | D10: 53.53 | E10: 0 | F10: 62.2 | G10: 199.98 | H10: 26.08 | I10: 0 | J10: 4.7 | K10: 0 | L10: 0 | M10: 0 | N10: 0 | O10: 0 | P10: 0 | Q10: =SUM(B10:P10) -> 469.26 | R10: 3.9 | S10: 4.33 | T10: 0 | V10: 0 | W10: 78.56 | X10: 78.39 | Y10: 76.41 | Z10: 0 | AB10: 0.75 | AC10: 180 | AD10: 13 | AE10: 0 | AF10: 5200 | AG10: =(V10*B10)+(W10*C10) -> 9644.8112 | AH10: =F10*X10 -> 4875.858 | AI10: =(D10*Y10)+(E10*Z10) -> 4090.2273
A11: =+A10+1 -> 46304 | B11: 0 | C11: 82.59 | D11: 54.48 | E11: 0 | F11: 87.74 | G11: 304.76 | H11: 33.44 | I11: 0 | J11: 24.61 | K11: 0 | L11: 0 | M11: 0 | N11: 0 | O11: 0 | P11: 0 | Q11: =SUM(B11:P11) -> 587.62 | R11: 5.87 | S11: 2.67 | T11: 0 | V11: 0 | W11: 78.55 | X11: 78.41 | Y11: 76.52 | Z11: 0 | AB11: 0.91666667 | AC11: 220 | AD11: 13 | AE11: 0 | AF11: 5000 | AG11: =(V11*B11)+(W11*C11) -> 6487.4445 | AH11: =F11*X11 -> 6879.6934 | AI11: =(D11*Y11)+(E11*Z11) -> 4168.8096
A12: =+A11+1 -> 46305 | B12: 0 | C12: 122.83 | D12: 59.49 | E12: 92.37 | F12: 119.76 | G12: 287.46 | H12: 9.74 | I12: 0 | J12: 10.4 | K12: 0 | L12: 0 | M12: 0 | N12: 0 | O12: 30.91 | P12: 0 | Q12: =SUM(B12:P12) -> 732.96 | R12: 6.14 | S12: 7.04 | T12: 0 | V12: 0 | W12: 78.21 | X12: 78.55 | Y12: 76.67 | Z12: 69.54 | AB12: 0.875 | AC12: 210 | AD12: 13 | AE12: 35000 | AF12: 5000 | AG12: =(V12*B12)+(W12*C12) -> 9606.5343 | AH12: =F12*X12 -> 9407.148 | AI12: =(D12*Y12)+(E12*Z12) -> 10984.508
A13: =+A12+1 -> 46306 | B13: 0 | C13: 78.17 | D13: 0 | E13: 0 | F13: 124.12 | G13: 215.06 | H13: 30.21 | I13: 0 | J13: 1.8 | K13: 0 | L13: 0 | M13: 0 | N13: 0 | O13: 0 | P13: 0 | Q13: =SUM(B13:P13) -> 449.36 | R13: 5.52 | S13: 3.13 | T13: 0 | V13: 0 | W13: 78.54 | X13: 79.15 | Y13: 0 | Z13: 0 | AB13: 0.875 | AC13: 210 | AD13: 13 | AE13: 0 | AF13: 6000 | AG13: =(V13*B13)+(W13*C13) -> 6139.4718 | AH13: =F13*X13 -> 9824.098 | AI13: =(D13*Y13)+(E13*Z13) -> 0
A14: =+A13+1 -> 46307 | B14: 0 | C14: 0 | D14: 14.05 | E14: 0 | F14: 91.83 | G14: 305.25 | H14: 13.84 | I14: 0 | J14: 5.3 | K14: 0 | L14: 0 | M14: 0 | N14: 1.36 | O14: 26 | P14: 0 | Q14: =SUM(B14:P14) -> 457.63 | R14: 5.88 | S14: 7.04 | T14: 0 | V14: 0 | W14: 0 | X14: 78.47 | Y14: 76.35 | Z14: 0 | AB14: 0.75 | AC14: 180 | AD14: 13 | AE14: 35000 | AF14: 5500 | AG14: =(V14*B14)+(W14*C14) -> 0 | AH14: =F14*X14 -> 7205.9001 | AI14: =(D14*Y14)+(E14*Z14) -> 1072.7175 | AJ14: Strip mill to SMS
A15: =+A14+1 -> 46308 | B15: 0 | C15: 128.61 | D15: 114.19 | E15: 0 | F15: 58.84 | G15: 262.4 | H15: 14.52 | I15: 0 | J15: 2.3 | K15: 0 | L15: 0 | M15: 0 | N15: 0 | O15: 0 | P15: 0 | Q15: =SUM(B15:P15) -> 580.86 | R15: 5.62 | S15: 2.59 | T15: 0 | V15: 0 | W15: 78.56 | X15: 78.44 | Y15: 76.71 | Z15: 0 | AB15: 0.875 | AC15: 210 | AD15: 12.98 | AE15: 34500 | AF15: 5200 | AG15: =(V15*B15)+(W15*C15) -> 10103.602 | AH15: =F15*X15 -> 4615.4096 | AI15: =(D15*Y15)+(E15*Z15) -> 8759.5149
A16: =+A15+1 -> 46309 | B16: 0 | C16: 40.29 | D16: 60.31 | E16: 0 | F16: 163.2 | G16: 314.46 | H16: 13.5 | I16: 0 | J16: 6.8 | K16: 0 | L16: 0 | M16: 0 | N16: 0 | O16: 0 | P16: 0 | Q16: =SUM(B16:P16) -> 598.56 | R16: 4.98 | S16: 7.53 | T16: 0 | V16: 0 | W16: 78.56 | X16: 78.65 | Y16: 77.02 | Z16: 0 | AB16: 0.875 | AC16: 210 | AD16: 13 | AE16: 0 | AF16: 5000 | AG16: =(V16*B16)+(W16*C16) -> 3165.1824 | AH16: =F16*X16 -> 12835.68 | AI16: =(D16*Y16)+(E16*Z16) -> 4645.0762
A17: =+A16+1 -> 46310 | B17: 0 | C17: 109.68 | D17: 25.1 | E17: 0 | F17: 66.33 | G17: 280.6 | H17: 26.92 | I17: 0 | J17: 5.5 | K17: 0 | L17: 0 | M17: 0 | N17: 0 | O17: 33.13 | P17: 0 | Q17: =SUM(B17:P17) -> 547.26 | R17: 6.23 | S17: 2.62 | T17: 0 | V17: 0 | W17: 78.55 | X17: 78.56 | Y17: 76.36 | Z17: 0 | AB17: 0.875 | AC17: 210 | AD17: 11.58 | AE17: 0 | AF17: 5500 | AG17: =(V17*B17)+(W17*C17) -> 8615.364 | AH17: =F17*X17 -> 5210.8848 | AI17: =(D17*Y17)+(E17*Z17) -> 1916.636
A18: =+A17+1 -> 46311 | B18: 0 | C18: 0 | D18: 25.44 | E18: 0 | F18: 85.25 | G18: 308.77 | H18: 15.32 | I18: 0 | J18: 8.4 | K18: 0 | L18: 0 | M18: 0 | N18: 0.31 | O18: 0 | P18: 0 | Q18: =SUM(B18:P18) -> 443.49 | R18: 5.77 | S18: 2.73 | T18: 0 | V18: 0 | W18: 0 | X18: 78.71 | Y18: 76.95 | Z18: 0 | AB18: 0.375 | AC18: 90 | AD18: 13 | AF18: 4500 | AG18: =(V18*B18)+(W18*C18) -> 0 | AH18: =F18*X18 -> 6710.0275 | AI18: =(D18*Y18)+(E18*Z18) -> 1957.608
A19: =+A18+1 -> 46312 | Q19: =SUM(B19:P19) -> 0 | AG19: =(V19*B19)+(W19*C19) -> 0 | AH19: =F19*X19 -> 0 | AI19: =(D19*Y19)+(E19*Z19) -> 0
A20: =+A19+1 -> 46313 | Q20: =SUM(B20:P20) -> 0 | AG20: =(V20*B20)+(W20*C20) -> 0 | AH20: =F20*X20 -> 0 | AI20: =(D20*Y20)+(E20*Z20) -> 0
A21: =+A20+1 -> 46314 | Q21: =SUM(B21:P21) -> 0 | AG21: =(V21*B21)+(W21*C21) -> 0 | AH21: =F21*X21 -> 0 | AI21: =(D21*Y21)+(E21*Z21) -> 0
A22: =+A21+1 -> 46315 | Q22: =SUM(B22:P22) -> 0 | AG22: =(V22*B22)+(W22*C22) -> 0 | AH22: =F22*X22 -> 0 | AI22: =(D22*Y22)+(E22*Z22) -> 0
A23: =+A22+1 -> 46316 | Q23: =SUM(B23:P23) -> 0 | AG23: =(V23*B23)+(W23*C23) -> 0 | AH23: =F23*X23 -> 0 | AI23: =(D23*Y23)+(E23*Z23) -> 0
A24: =+A23+1 -> 46317 | Q24: =SUM(B24:P24) -> 0 | AG24: =(V24*B24)+(W24*C24) -> 0 | AH24: =F24*X24 -> 0 | AI24: =(D24*Y24)+(E24*Z24) -> 0
A25: =+A24+1 -> 46318 | Q25: =SUM(B25:P25) -> 0 | AG25: =(V25*B25)+(W25*C25) -> 0 | AH25: =F25*X25 -> 0 | AI25: =(D25*Y25)+(E25*Z25) -> 0
A26: =+A25+1 -> 46319 | Q26: =SUM(B26:P26) -> 0 | AG26: =(V26*B26)+(W26*C26) -> 0 | AH26: =F26*X26 -> 0 | AI26: =(D26*Y26)+(E26*Z26) -> 0
A27: =+A26+1 -> 46320 | Q27: =SUM(B27:P27) -> 0 | AG27: =(V27*B27)+(W27*C27) -> 0 | AH27: =F27*X27 -> 0 | AI27: =(D27*Y27)+(E27*Z27) -> 0
A28: =+A27+1 -> 46321 | Q28: =SUM(B28:P28) -> 0 | AG28: =(V28*B28)+(W28*C28) -> 0 | AH28: =F28*X28 -> 0 | AI28: =(D28*Y28)+(E28*Z28) -> 0
A29: =+A28+1 -> 46322 | Q29: =SUM(B29:P29) -> 0 | AG29: =(V29*B29)+(W29*C29) -> 0 | AH29: =F29*X29 -> 0 | AI29: =(D29*Y29)+(E29*Z29) -> 0
A30: =+A29+1 -> 46323 | Q30: =SUM(B30:P30) -> 0 | AG30: =(V30*B30)+(W30*C30) -> 0 | AH30: =F30*X30 -> 0 | AI30: =(D30*Y30)+(E30*Z30) -> 0
... A32: =+A31+1 -> 46325 | Q32: =SUM(B32:P32) -> 0 | AG32: =(V32*B32)+(W32*C32) -> 0 | AH32: =F32*X32 -> 0 | AI32: =(D32*Y32)+(E32*Z32) -> 0
A33: =+A32+1 -> 46326 | B33: =SUM(B3:B32) -> 0 | C33: 0 | D33: 0 | E33: 0 | Q33: =SUM(B33:P33) -> 0 | AG33: =(V33*B33)+(W33*C33) -> 0 | AH33: =F33*X33 -> 0 | AI33: =(D33*Y33)+(E33*Z33) -> 0
A34: TOTAL | B34: =SUM(B3:B33) -> 0 | C34: =SUM(C3:C33) -> 805.21 | D34: =SUM(D3:D33) -> 681.36 | E34: =SUM(E3:E32) -> 141.85 | F34: =SUM(F3:F33) -> 1701.93 | G34: =SUM(G3:G33) -> 4202.05 | H34: =SUM(H3:H33) -> 283.08 | I34: =SUM(I3:I33) -> 0 | J34: =SUM(J3:J33) -> 85.81 | K34: =SUM(K3:K33) -> 0 | L34: =SUM(L3:L33) -> 0 | M34: =SUM(M3:M33) -> 0 | ... T34: =SUM(T3:T33) -> 0 | V34: =AVERAGE(V3:V33) -> 0 | W34: =AVERAGE(W3:W33) -> 44.035625 | X34: =AVERAGE(X3:X33) -> 78.80875 | Y34: =AVERAGE(Y3:Y33) -> 67.119375 | Z34: =AVERAGE(Z3:Z33) -> 8.695 | AB34: =SUM(AB3:AB33) -> 13.208333 | AC34: =SUM(AC3:AC33) -> 3170 | AD34: =AVERAGE(AD3:AD33) -> 12.91 | AE34: =SUM(AE3:AE33) -> 104500 | AF34: =SUM(AF3:AF33) -> 82600 | AG34: =SUM(AG3:AG33) -> 63044.342 | AH34: =SUM(AH3:AH33) -> 134228.3 | AI34: =SUM(AI3:AI33) -> 62146.782
V35: =SUM(V3:V34) -> 0
G36: =(G34+J34) -> 4287.86 | H36: =H34+N34 -> 290.78 | AG36: =AG34/(B34+C34) -> 78.295528 | AH36: =AH34/F34 -> 78.868284 | AI36: =AI34/(D34+E34) -> 75.49323
D39: =B34+D34+F34+C34 -> 3188.5

Sheet Issue 
A1: CONSUMPTION | S1: =[1]monthly!L26 -> 389.84743 | T1: <---Target
A3: DATE | B3: LUMPS | C3: LUMPS OUTSIDE | D3: OUT FINES | E3: FINES | F3: PELLET | G3: SCRAP | H3: Slag iron (MAG) | I3: Over Size MAG | J3: Rolling Scrap | K3: MS Scrap | L3: PIG IRON SPLASHES | M3: CI mix Scrap | N3: GRANULES OF PIG IRON | O3: PIG IRON | P3: CI SKULL | Q3: BILLET END CUT | R3: SLAGE WASTE | S3: TOTAL | T3: PROD | U3: BILLET END CUT | V3: RAW SLAG | W3: YIELD | X3: Total Heat | Y3: BAG FILTER DUST | Z3: SLAG JAM | AA3: MILL SCALE | AB3: Furnuce Power | AC3: Auxiliary Power | AD3: Shearing M/c
A4: 46296 | B4: 0 | C4: 75 | D4: 10 | E4: 30 | F4: 114 | G4: 194 | H4: 10 | I4: 0 | J4: 10 | K4: 19.31 | L4: 0 | M4: 8 | N4: 0 | O4: 0 | P4: 0 | Q4: 0 | R4: 0 | S4: =SUM(B4:R4) -> 470.31 | T4: 403.622 | U4: 5.37 | V4: 0 | W4: =+T4/S4*100 -> 85.820416 | X4: 12 | Y4: 0.61 | Z4: 0 | AA4: 1.5 | AB4: 264272 | AC4: 25182 | AD4: 3676 | AE4: =AD4/Recieving!AC3 -> 16.709091
A5: =+A4+1 -> 46297 | B5: 0 | C5: 68 | D5: 22.5 | E5: 22.5 | F5: 127 | G5: 208 | H5: 10 | I5: 0 | J5: 12 | K5: 0 | L5: 0 | M5: 3 | N5: 0 | O5: 2 | P5: 0 | Q5: 0 | R5: 0 | S5: =SUM(B5:R5) -> 475 | T5: 407.327 | U5: 3.07 | V5: 90.69 | W5: =+T5/S5*100 -> 85.753053 | X5: 12 | Y5: 0.5 | Z5: 9.53 | AA5: 1 | AB5: 268056 | AC5: 23124 | AD5: 2730 | AE5: =AD5/Recieving!AC4 -> 15.166667
A6: =+A5+1 -> 46298 | B6: 0 | C6: 65 | D6: 26 | E6: 26 | F6: 112 | G6: 224 | H6: 7 | I6: 0 | J6: 12 | K6: 0 | L6: 0 | M6: 0 | N6: 0 | O6: 0 | P6: 0 | Q6: 0 | R6: 0 | S6: =SUM(B6:R6) -> 472 | T6: 408.765 | U6: 5.1 | V6: 81.73 | W6: =+T6/S6*100 -> 86.602754 | X6: 12 | Y6: 0.46 | Z6: 7.35 | AA6: 1 | AB6: 264594 | AC6: 23009 | AD6: 2626 | AE6: =AD6/Recieving!AC5 -> 13.821053
A7: =+A6+1 -> 46299 | B7: 0 | C7: 68 | D7: 25 | E7: 25 | F7: 120 | G7: 215 | H7: 6 | I7: 0 | J7: 15 | K7: 0 | L7: 0 | M7: 0 | N7: 0 | O7: 0 | P7: 0 | Q7: 0 | R7: 0 | S7: =SUM(B7:R7) -> 474 | T7: 407.296 | U7: 6.64 | V7: 129.7 | W7: =+T7/S7*100 -> 85.927426 | X7: 12 | Y7: 0.45 | Z7: 3.86 | AA7: 1 | AB7: 266489 | AC7: 23980 | AD7: 3155 | AE7: =AD7/Recieving!AC6 -> 15.775
A8: =+A7+1 -> 46300 | C8: 70 | D8: 20 | E8: 20 | F8: 110 | G8: 230 | H8: 12 | I8: 0 | J8: 20 | K8: 0 | L8: 0 | M8: 0 | N8: 0 | O8: 0 | P8: 0 | Q8: 0 | R8: 0 | S8: =SUM(B8:R8) -> 482 | T8: 416.405 | U8: 6.05 | V8: 68.87 | W8: =+T8/S8*100 -> 86.391079 | X8: 12 | Y8: 0.53 | Z8: 2.79 | AA8: 1 | AB8: 269485 | AC8: 23612 | AD8: 3240 | AE8: =AD8/Recieving!AC7 -> 14.727273
A9: =+A8+1 -> 46301 | B9: 0 | C9: 75 | D9: 22.5 | E9: 22.5 | F9: 100 | G9: 235 | H9: 10 | I9: 0 | J9: 10 | K9: 0 | L9: 0 | M9: 0 | N9: 0 | O9: 0 | P9: 0 | Q9: 0 | R9: 0 | S9: =SUM(B9:R9) -> 475 | T9: 410.068 | U9: 6.07 | V9: 83.49 | W9: =+T9/S9*100 -> 86.330105 | X9: 12 | Y9: 0.65 | Z9: 2.8 | AA9: 1 | AB9: 265167 | AC9: 22547 | AD9: 3917 | AE9: =AD9/Recieving!AC8 -> 17.804545
A10: =+A9+1 -> 46302 | C10: 65 | D10: 25 | E10: 35 | F10: 100 | G10: 235 | H10: 5 | I10: 0 | J10: 15 | K10: 0 | L10: 0 | M10: 0 | N10: 0 | O10: 0 | P10: 0 | Q10: 0 | R10: 0 | S10: =SUM(B10:R10) -> 480 | T10: 412.895 | U10: 5.52 | V10: 62.25 | W10: =+T10/S10*100 -> 86.019792 | X10: 12 | Y10: 0.55 | Z10: 0 | AA10: 1 | AB10: 265083 | AC10: 24448 | AD10: 3728 | AE10: =AD10/Recieving!AC9 -> 16.945455
A11: =+A10+1 -> 46303 | B11: 0 | C11: 60 | D11: 31 | E11: 31 | F11: 110 | G11: 232 | H11: 5 | I11: 0 | J11: 15 | K11: 0 | L11: 0 | M11: 0 | N11: 0 | O11: 0 | P11: 0 | Q11: 0 | R11: 0 | S11: =SUM(B11:R11) -> 484 | T11: 414.606 | U11: 3.9 | V11: 79.75 | W11: =+T11/S11*100 -> 85.662397 | X11: 12 | Y11: 0.71 | Z11: 4.33 | AA11: 2 | AB11: 271922 | AC11: 24235 | AD11: 2699 | AE11: =AD11/Recieving!AC10 -> 14.994444
A12: =+A11+1 -> 46304 | B12: 0 | C12: 60 | D12: 32 | E12: 33 | F12: 102 | G12: 228 | H12: 5 | I12: 0 | J12: 15 | K12: 0 | L12: 0 | M12: 0 | N12: 0 | O12: 0 | P12: 0 | Q12: 0 | R12: 0 | S12: =SUM(B12:R12) -> 475 | T12: 408.074 | U12: 5.87 | V12: 100.63 | W12: =+T12/S12*100 -> 85.910316 | X12: 12 | Y12: 0.64 | Z12: 2.67 | AA12: 4 | AB12: 264519 | AC12: 22791 | AD12: 3706 | AE12: =AD12/Recieving!AC11 -> 16.845455
A13: =+A12+1 -> 46305 | B13: 0 | C13: 55 | D13: 25 | E13: 40 | F13: 108 | G13: 226 | H13: 5 | I13: 0 | J13: 14 | K13: 0 | L13: 0 | M13: 0 | N13: 0 | O13: 0 | P13: 0 | Q13: 0 | R13: 0 | S13: =SUM(B13:R13) -> 473 | T13: 407.296 | U13: 6.14 | V13: 102.88 | W13: =+T13/S13*100 -> 86.109091 | X13: 12 | Y13: 0.6 | Z13: 7.04 | AA13: 4 | AB13: 265538 | AC13: 23852 | AD13: 3169 | AE13: =AD13/Recieving!AC12 -> 15.090476
A14: =+A13+1 -> 46306 | B14: 0 | C14: 67 | D14: 27 | E14: 28 | F14: 98 | G14: 228 | H14: 10 | I14: 0 | J14: 14 | K14: 0 | L14: 0 | M14: 0 | N14: 0 | O14: 0 | P14: 0 | Q14: 0 | R14: 0 | S14: =SUM(B14:R14) -> 472 | T14: 406.175 | U14: 5.52 | V14: 107.39 | W14: =+T14/S14*100 -> 86.054025 | X14: 12 | Y14: 0.61 | Z14: 3.13 | AA14: 4 | AB14: 265637 | AC14: 23560 | AD14: 3580 | AE14: =AD14/Recieving!AC13 -> 17.047619
A15: =+A14+1 -> 46307 | C15: 75 | D15: 27 | E15: 28 | F15: 100 | G15: 222 | H15: 8 | I15: 0 | J15: 10 | K15: 0 | L15: 0 | M15: 0 | N15: 0 | O15: 0 | P15: 0 | Q15: 0 | R15: 0 | S15: =SUM(B15:R15) -> 470 | T15: 403.765 | U15: 5.88 | V15: 91.11 | W15: =+T15/S15*100 -> 85.907447 | X15: 12 | Y15: 0.36 | Z15: 7.04 | AA15: 4 | AB15: 263593 | AC15: 22743 | AD15: 2555 | AE15: =AD15/Recieving!AC14 -> 14.194444
A16: =+A15+1 -> 46308 | C16: 78 | D16: 27 | E16: 28 | F16: 95 | G16: 224 | H16: 10 | I16: 0 | J16: 10 | K16: 0 | L16: 0 | M16: 0 | N16: 0 | O16: 0 | P16: 0 | Q16: 0 | R16: 0 | S16: =SUM(B16:R16) -> 472 | T16: 404.764 | U16: 5.62 | V16: 19.12 | W16: =+T16/S16*100 -> 85.755085 | X16: 12 | Y16: 0.71 | Z16: 2.59 | AA16: 5 | AB16: 264964 | AC16: 22750 | AD16: 3378 | AE16: =AD16/Recieving!AC15 -> 16.085714
A17: =+A16+1 -> 46309 | B17: 0 | C17: 76 | D17: 30 | E17: 30 | F17: 82 | G17: 222 | H17: 12 | I17: 0 | J17: 22 | K17: 0 | L17: 0 | M17: 0 | N17: 0 | O17: 0 | P17: 0 | Q17: 0 | R17: 0 | S17: =SUM(B17:R17) -> 474 | T17: 407.776 | U17: 4.98 | V17: 113.89 | W17: =+T17/S17*100 -> 86.028692 | X17: 12 | Y17: 0.66 | Z17: 7.53 | AA17: 5 | AB17: 267725 | AC17: 25475 | AD17: 2706 | AE17: =AD17/Recieving!AC16 -> 12.885714
A18: =+A17+1 -> 46310 | B18: 0 | C18: 75 | D18: 24 | E18: 24 | F18: 65 | G18: 165 | H18: 10 | I18: 0 | J18: 30 | K18: 0 | L18: 0 | M18: 0 | N18: 0 | O18: 0 | P18: 0 | Q18: 0 | R18: 0 | S18: =SUM(B18:R18) -> 393 | T18: 337.797 | U18: 6.23 | V18: 62.02 | W18: =+T18/S18*100 -> 85.953435 | X18: 10 | Y18: 0.33 | Z18: 2.62 | AA18: 4 | AB18: 229313 | AC18: 20823 | AD18: 3501 | AE18: =AD18/Recieving!AC17 -> 16.671429
A19: =+A18+1 -> 46311 | B19: 0 | C19: 85 | D19: 27 | E19: 28 | F19: 90 | G19: 222 | H19: 5 | I19: 0 | J19: 20 | K19: 0 | L19: 0 | M19: 0 | N19: 0 | O19: 0 | P19: 0 | Q19: 0 | R19: 0 | S19: =SUM(B19:R19) -> 477 | T19: 409.078 | U19: 5.77 | V19: 119.05 | W19: =+T19/S19*100 -> 85.760587 | X19: 12 | Y19: 0 | Z19: 2.73 | AA19: 5 | AB19: 264107 | AC19: 23401 | AD19: 2533 | AE19: =AD19/Recieving!AC18 -> 28.144444
A20: =+A19+1 -> 46312 | S20: =SUM(B20:R20) -> 0 | W20: =+T20/S20*100 -> #DIV/0! | AE20: =AD20/Recieving!AC19 -> #DIV/0!
A21: =+A20+1 -> 46313 | S21: =SUM(B21:R21) -> 0 | W21: =+T21/S21*100 -> #DIV/0! | AE21: =AD21/Recieving!AC20 -> #DIV/0!
A22: =+A21+1 -> 46314 | S22: =SUM(B22:R22) -> 0 | W22: =+T22/S22*100 -> #DIV/0! | AE22: =AD22/Recieving!AC21 -> #DIV/0!
A23: =+A22+1 -> 46315 | S23: =SUM(B23:R23) -> 0 | W23: =+T23/S23*100 -> #DIV/0! | AE23: =AD23/Recieving!AC22 -> #DIV/0!
A24: =+A23+1 -> 46316 | S24: =SUM(B24:R24) -> 0 | W24: =+T24/S24*100 -> #DIV/0! | AE24: =AD24/Recieving!AC23 -> #DIV/0!
A25: =+A24+1 -> 46317 | S25: =SUM(B25:R25) -> 0 | W25: =+T25/S25*100 -> #DIV/0! | AE25: =AD25/Recieving!AC24 -> #DIV/0!
A26: =+A25+1 -> 46318 | S26: =SUM(B26:R26) -> 0 | W26: =+T26/S26*100 -> #DIV/0! | AE26: =AD26/Recieving!AC25 -> #DIV/0!
A27: =+A26+1 -> 46319 | S27: =SUM(B27:R27) -> 0 | W27: =+T27/S27*100 -> #DIV/0! | AE27: =AD27/Recieving!AC26 -> #DIV/0!
A28: =+A27+1 -> 46320 | S28: =SUM(B28:R28) -> 0 | W28: =+T28/S28*100 -> #DIV/0! | AE28: =AD28/Recieving!AC27 -> #DIV/0!
A29: =+A28+1 -> 46321 | S29: =SUM(B29:R29) -> 0 | W29: =+T29/S29*100 -> #DIV/0! | AE29: =AD29/Recieving!AC28 -> #DIV/0!
A30: =+A29+1 -> 46322 | S30: =SUM(B30:R30) -> 0 | W30: =+T30/S30*100 -> #DIV/0! | AE30: =AD30/Recieving!AC29 -> #DIV/0!
A31: =+A30+1 -> 46323 | S31: =SUM(B31:R31) -> 0 | W31: =+T31/S31*100 -> #DIV/0! | AE31: =AD31/Recieving!AC30 -> #DIV/0!
... A34: =+A33+1 -> 46326 | S34: =SUM(B34:R34) -> 0 | W34: =+T34/S34*100 -> #DIV/0! | AE34: =AD34/Recieving!AC33 -> #DIV/0!
A35: TOTAL | B35: =SUM(B4:B34) -> 0 | C35: =SUM(C4:C34) -> 1117 | D35: =SUM(D4:D34) -> 401 | E35: =SUM(E4:E34) -> 451 | F35: =SUM(F4:F34) -> 1633 | G35: =SUM(G4:G34) -> 3510 | H35: =SUM(H4:H34) -> 130 | I35: =SUM(I4:I34) -> 0 | ... V35: =SUM(V4:V34) -> 1312.57 | W35: =+T35/S35*100 -> 85.9995 | X35: =SUM(X4:X34) -> 190 | Y35: =SUM(Y4:Y34) -> 8.37 | Z35: =SUM(Z4:Z34) -> 66.01 | AA35: =SUM(AA4:AA34) -> 44.5 | AB35: =SUM(AB4:AB34) -> 4220464 | AC35: =SUM(AC4:AC34) -> 375532 | AD35: =SUM(AD4:AD34) -> 50899
AC36: =+AB35+AC35+AD35 -> 4646895
G38: =G35+[2]Recieving!J34 -> 3572.81 | M38: =M35+M37 -> 11

Sheet Slag Crusher 
A1: SLAG CRUSHER REPORT October-2026
A2: DATE | B2: RAW SLAG OPENING | C2: RAW SLAG PRODUCTION | D2: TOTAL RAW SLAG | E2: RAW SLAG TRANSFER TO SLAG CRUSHER | F2: RAW SLAG CONSUMPTION | G2: RAW SLAG BALANCE | H2: MAG MATERIAL RECEIVED | I2: SLAG JAM RECEIVED | J2: OVER SIZE MAG
A3: 46296 | B3: 189.664 | C3: 80 | D3: =C3+B3 -> 269.664 | E3: 63.66 | F3: 140 | G3: =D3-F3 -> 129.664 | H3: 33.41 | I3: 0 | J3: 0
A4: 46297 | B4: =G3 -> 129.664 | C4: 70 | D4: =C4+B4 -> 199.664 | E4: 90.69 | F4: 9.53 | G4: =D4-F4 -> 190.134 | H4: 0 | I4: 9.53 | J4: 0
A5: 46298 | B5: =G4 -> 190.134 | C5: 80 | D5: =C5+B5 -> 270.134 | E5: 81.73 | F5: 7.35 | G5: =D5-F5 -> 262.784 | H5: 0 | I5: 7.35 | J5: 0
A6: 46299 | B6: =G5 -> 262.784 | C6: 105 | D6: =C6+B6 -> 367.784 | E6: 129.7 | F6: 3.86 | G6: =D6-F6 -> 363.924 | H6: 0 | I6: 3.86 | J6: 0 | N6: 0
A7: 46300 | B7: =G6 -> 363.924 | C7: 70 | D7: =C7+B7 -> 433.924 | E7: 68.87 | F7: 2.79 | G7: =D7-F7 -> 431.134 | H7: 0 | I7: 2.79 | J7: 0
A8: 46301 | B8: =G7 -> 431.134 | C8: 80 | D8: =C8+B8 -> 511.134 | E8: 83.49 | F8: 341 | G8: =D8-F8 -> 170.134 | H8: 34.18 | I8: 2.8 | J8: 0
A9: 46302 | B9: =G8 -> 170.134 | C9: 70 | D9: =C9+B9 -> 240.134 | E9: 62.25 | F9: 0 | G9: =D9-F9 -> 240.134 | H9: 0 | I9: 0 | J9: 0
A10: 46303 | B10: =G9 -> 240.134 | C10: 70 | D10: =C10+B10 -> 310.134 | E10: 79.75 | F10: 4.33 | G10: =D10-F10 -> 305.804 | H10: 0 | I10: 4.33 | J10: 0
A11: 46304 | B11: =G10 -> 305.804 | C11: 100 | D11: =C11+B11 -> 405.804 | E11: 100.63 | F11: 2.67 | G11: =D11-F11 -> 403.134 | H11: 0 | I11: 2.67
A12: 46305 | B12: =G11 -> 403.134 | C12: 120 | D12: =C12+B12 -> 523.134 | E12: 102.88 | F12: 310 | G12: =D12-F12 -> 213.134 | H12: 30.91 | I12: 7.04
A13: 46306 | B13: =G12 -> 213.134 | C13: 100 | D13: =C13+B13 -> 313.134 | E13: 107.39 | F13: 3.13 | G13: =D13-F13 -> 310.004 | H13: 0 | I13: 3.13
A14: 46307 | B14: =G13 -> 310.004 | C14: 130 | D14: =C14+B14 -> 440.004 | E14: 91.11 | F14: 270 | G14: =D14-F14 -> 170.004 | H14: 26 | I14: 7.04
A15: 46308 | B15: =G14 -> 170.004 | C15: 80 | D15: =C15+B15 -> 250.004 | E15: 19.12 | F15: 2.59 | G15: =D15-F15 -> 247.414 | H15: 0 | I15: 2.59
A16: 46309 | B16: =G15 -> 247.414 | C16: 70 | D16: =C16+B16 -> 317.414 | E16: 113.89 | F16: 7.53 | G16: =D16-F16 -> 309.884 | H16: 0 | I16: 7.53
A17: 46310 | B17: =G16 -> 309.884 | C17: 100 | D17: =C17+B17 -> 409.884 | E17: 62.02 | F17: 300 | G17: =D17-F17 -> 109.884 | H17: 33.13 | I17: 2.62
A18: 46311 | B18: =G17 -> 109.884 | D18: =C18+B18 -> 109.884 | G18: =D18-F18 -> 109.884
A19: 46312 | B19: =G18 -> 109.884 | D19: =C19+B19 -> 109.884 | G19: =D19-F19 -> 109.884
A20: 46313 | B20: =G19 -> 109.884 | D20: =C20+B20 -> 109.884 | G20: =D20-F20 -> 109.884
A21: 46314 | B21: =G20 -> 109.884 | D21: =C21+B21 -> 109.884 | G21: =D21-F21 -> 109.884
A22: 46315 | B22: =G21 -> 109.884 | D22: =C22+B22 -> 109.884 | G22: =D22-F22 -> 109.884
A23: 46316 | B23: =G22 -> 109.884 | D23: =C23+B23 -> 109.884 | G23: =D23-F23 -> 109.884
A24: 46317 | B24: =G23 -> 109.884 | D24: =C24+B24 -> 109.884 | G24: =D24-F24 -> 109.884
A25: 46318 | B25: =G24 -> 109.884 | D25: =C25+B25 -> 109.884 | G25: =D25-F25 -> 109.884
A26: 46319 | B26: =G25 -> 109.884 | D26: =C26+B26 -> 109.884 | G26: =D26-F26 -> 109.884
A27: 46320 | B27: =G26 -> 109.884 | D27: =C27+B27 -> 109.884 | G27: =D27-F27 -> 109.884
A28: 46321 | B28: =G27 -> 109.884 | D28: =C28+B28 -> 109.884 | G28: =D28-F28 -> 109.884
A29: 46322 | B29: =G28 -> 109.884 | D29: =C29+B29 -> 109.884 | G29: =D29-F29 -> 109.884
... A33: 46326 | B33: =G32 -> 109.884 | D33: =C33+B33 -> 109.884 | G33: =D33-F33 -> 109.884
C34: =SUM(C3:C33) -> 1325 | E34: =SUM(E3:E33) -> 1257.18 | F34: =SUM(F3:F33) -> 1404.78 | H34: =SUM(H3:H33) -> 157.63 | I34: =SUM(I3:I33) -> 63.28 | J34: =SUM(J3:J33) -> 0
E36: MAG OUT % | F36: =H34/F34*100 -> 11.220974

Sheet Monthly
A1: October Month Daily Working Report -2026 | N1: Total Working Days | P1: =W22 -> 16 | R1: MIEPL@1
A2: SMS Stock and Consumption reports. | O2: Approved Charge Mix %
A3: Sl no | B3: Particular | D3: Opening | E3: Received | F3: Total | G3: Issue | H3: Closing | I3: % Target Consp. | J3: % Actual cons. | K3: Metal conv. | L3: Assumed yield % | M3: %Fe(M) | O3: Item | P3: CM1 | Q3: CM2 | R3: CM3 | S3: CM4 | T3: CM5 | U3: CM6 | V3: CM7 | W3: Avg
A4: 1 | B4: SPONGE IRON LUMPS | D4: 690.95 | E4: =Recieving!C34 -> 805.21 | F4: =(D4+E4) -> 1496.16 | G4: ='Issue '!C35 -> 1117 | H4: =+F4-G4 -> 379.16 | I4: =W4 -> 16 | J4: =(G4/$G$17)*100 -> 14.857062 | K4: =J4*L4 -> 11.929557 | L4: =M4/100+2% -> 0.80295528 | M4: =Recieving!AG36 -> 78.295528 | O4: SPONGE IRON LUMPS | P4: 16 | Q4: 16 | R4: 16 | S4: 0 | T4: 0 | U4: 0 | V4: 0 | W4: =(P4*$P$22+Q4*$Q$22+R4*$R$22+S4*$S$22+T4*$T$22+U4*$U$22+V4*$V$22)/$W$22 -> 16
A5: 2 | B5: SPONGE IRON FINES | D5: 272.86 | E5: =Recieving!D34+Recieving!E34 -> 823.21 | F5: =(D5+E5) -> 1096.07 | G5: ='Issue '!D35+'Issue '!E35 -> 852 | H5: =+F5-G5 -> 244.07 | I5: =W5 -> 11.25 | J5: =(G5/$G$17)*100 -> 11.332334 | K5: =J5*L5 -> 8.5551449 | L5: =M5/100 -> 0.7549323 | M5: =Recieving!AI36 -> 75.49323 | O5: SPONGE IRON FINES | P5: 6 | Q5: 13 | R5: 13 | S5: 0 | T5: 0 | U5: 0 | V5: 0 | W5: =(P5*$P$22+Q5*$Q$22+R5*$R$22+S5*$S$22+T5*$T$22+U5*$U$22+V5*$V$22)/$W$22 -> 11.25
A6: 3 | B6: SPONGE IRON PELLETS | D6: 131.63 | E6: =Recieving!F34 -> 1701.93 | F6: =(D6+E6) -> 1833.56 | G6: ='Issue '!F35 -> 1633 | H6: =+F6-G6 -> 200.56 | I6: =W6 -> 19.5 | J6: =(G6/$G$17)*100 -> 21.720307 | K6: =J6*L6 -> 17.130433 | L6: =M6/100 -> 0.78868284 | M6: =Recieving!AH36 -> 78.868284 | O6: SPONGE IRON PELLETS | P6: 27 | Q6: 17 | R6: 17 | S6: 0 | T6: 0 | U6: 0 | V6: 0 | W6: =(P6*$P$22+Q6*$Q$22+R6*$R$22+S6*$S$22+T6*$T$22+U6*$U$22+V6*$V$22)/$W$22 -> 19.5
A7: 4 | B7: PIG IRON | D7: 316.55 | E7: =Recieving!L34 -> 0 | F7: =(D7+E7) -> 316.55 | G7: ='Issue '!O35 -> 2 | H7: =(+F7-G7)-10.09 -> 304.46 | I7: =W7 -> 1.75 | J7: =(G7/$G$17)*100 -> 0.026601723 | K7: =J7*L7 -> 0.02500562 | L7: 0.94 | N7: 10.090 mt pig iron transfer to vihan casting | O7: PIG IRON | P7: 4 | Q7: 1 | R7: 1 | S7: 0 | T7: 0 | U7: 0 | V7: 0 | W7: =(P7*$P$22+Q7*$Q$22+R7*$R$22+S7*$S$22+T7*$T$22+U7*$U$22+V7*$V$22)/$W$22 -> 1.75
A8: 5 | B8: SCRAP | D8: 549.669 | E8: =Recieving!G34 -> 4202.05 | F8: =(D8+E8) -> 4751.719 | G8: ='Issue '!G35 -> 3510 | H8: =(+F8-G8)-0.13 -> 1241.589 | I8: =W8 -> 46 | J8: =(G8/$G$17)*100 -> 46.686024 | K8: =J8*L8 -> 43.418002 | L8: 0.93 | N8: 0.130 mt transfer to strip mill | O8: SCRAP | P8: 40 | Q8: 48 | R8: 48 | S8: 0 | T8: 0 | U8: 0 | V8: 0 | W8: =(P8*$P$22+Q8*$Q$22+R8*$R$22+S8*$S$22+T8*$T$22+U8*$U$22+V8*$V$22)/$W$22 -> 46
A9: 6 | B9: GRANULES OF PIG IRON | D9: 0 | E9: =Recieving!K34 -> 0 | F9: =(D9+E9) -> 0 | G9: ='Issue '!N35 -> 0 | H9: =+F9-G9 -> 0 | I9: =W9 -> 0 | J9: =(G9/$G$17)*100 -> 0 | K9: =J9*L9 -> 0 | L9: 0.91 | O9: GRANULES OF PIG IRON | P9: 0 | Q9: 0 | R9: 0 | S9: 0 | T9: 0 | U9: 0 | V9: 0 | W9: =(P9*$P$22+Q9*$Q$22+R9*$R$22+S9*$S$22+T9*$T$22+U9*$U$22+V9*$V$22)/$W$22 -> 0
A10: 7 | B10: MS SCRAP- ROLLING MILL | D10: 33.61 | E10: =Recieving!H34 -> 283.08 | F10: =(D10+E10) -> 316.69 | G10: ='Issue '!J35 -> 244 | H10: =+F10-G10 -> 72.69 | I10: =W10 -> 3 | J10: =(G10/$G$17)*100 -> 3.2454102 | K10: =J10*L10 -> 3.180502 | L10: 0.98 | O10: MS SCRAP- ROLLING MILL | P10: 3 | Q10: 3 | R10: 3 | S10: 0 | T10: 0 | U10: 0 | V10: 0 | W10: =(P10*$P$22+Q10*$Q$22+R10*$R$22+S10*$S$22+T10*$T$22+U10*$U$22+V10*$V$22)/$W$22 -> 3
A11: 8 | B11: PIG IRON SPLASHES | D11: 0 | E11: =Recieving!I34 -> 0 | F11: =(D11+E11) -> 0 | G11: ='Issue '!L35 -> 0 | H11: =+F11-G11 -> 0 | I11: =W11 -> 0 | J11: =(G11/$G$17)*100 -> 0 | K11: =J11*L11 -> 0 | L11: 0.88 | O11: PIG IRON SPLASHES | P11: 0 | Q11: 0 | R11: 0 | S11: 0 | T11: 0 | U11: 0 | V11: 0 | W11: =(P11*$P$22+Q11*$Q$22+R11*$R$22+S11*$S$22+T11*$T$22+U11*$U$22+V11*$V$22)/$W$22 -> 0
A12: 9 | B12: CI mix Scrap | D12: 33.025 | E12: =Recieving!J34 -> 85.81 | F12: =(D12+E12) -> 118.835 | G12: ='Issue '!M35 -> 11 | H12: =+F12-G12 -> 107.835 | I12: =W12 -> 0.25 | J12: =(G12/$G$17)*100 -> 0.14630948 | K12: =J12*L12 -> 0.13167853 | L12: 0.9 | N12: =H8+H10+H14 -> 1321.979 | O12: CI mix Scrap | P12: 1 | Q12: 0 | R12: 0 | S12: 0 | T12: 0 | U12: 0 | V12: 0 | W12: =(P12*$P$22+Q12*$Q$22+R12*$R$22+S12*$S$22+T12*$T$22+U12*$U$22+V12*$V$22)/$W$22 -> 0.25
A13: 10 | B13: CI SKULL | D13: 0 | E13: =Recieving!M34 -> 0 | F13: =(D13+E13) -> 0 | G13: ='Issue '!P35 -> 0 | H13: =+F13-G13 -> 0 | I13: =W13 -> 0 | J13: =(G13/$G$17)*100 -> 0 | K13: =J13*L13 -> 0 | L13: 0.93 | O13: CI SKULL | P13: 0 | Q13: 0 | R13: 0 | S13: 0 | T13: 0 | U13: 0 | V13: 0 | W13: =(P13*$P$22+Q13*$Q$22+R13*$R$22+S13*$S$22+T13*$T$22+U13*$U$22+V13*$V$22)/$W$22 -> 0
A14: 11 | B14: MS SCRAP | D14: 19.31 | E14: =Recieving!N34 -> 7.7 | F14: =(D14+E14) -> 27.01 | G14: ='Issue '!K35 -> 19.31 | H14: =+F14-G14 -> 7.7 | I14: =W14 -> 0 | J14: =(G14/$G$17)*100 -> 0.25683964 | K14: =J14*L14 -> 0.24142926 | L14: 0.94 | O14: MS SCRAP | P14: 0 | Q14: 0 | R14: 0 | S14: 0 | T14: 0 | U14: 0 | V14: 0 | W14: =(P14*$P$22+Q14*$Q$22+R14*$R$22+S14*$S$22+T14*$T$22+U14*$U$22+V14*$V$22)/$W$22 -> 0
A15: 12 | B15: OVER SIZE MAG | D15: 0 | E15: =Recieving!P34 -> 0 | F15: =(D15+E15) -> 0 | G15: ='Issue '!I35 -> 0 | H15: =+F15-G15 -> 0 | I15: =W15 -> 0 | J15: =(G15/$G$17)*100 -> 0 | K15: =J15*L15 -> 0 | L15: 0.68 | O15: OVER SIZE MAG | P15: 0 | Q15: 0 | R15: 0 | S15: 0 | T15: 0 | U15: 0 | V15: 0 | W15: =(P15*$P$22+Q15*$Q$22+R15*$R$22+S15*$S$22+T15*$T$22+U15*$U$22+V15*$V$22)/$W$22 -> 0
A16: 13 | B16: SLAG METAL (Mag Material) | D16: 12.35 | E16: =Recieving!O34 -> 157.63 | F16: =(D16+E16) -> 169.98 | G16: ='Issue '!H35 -> 130 | H16: =+F16-G16 -> 39.98 | I16: =W16 -> 2.25 | J16: =(G16/$G$17)*100 -> 1.729112 | K16: =J16*L16 -> 1.1868625 | L16: 0.6864 | O16: SLAG METAL | P16: 3 | Q16: 2 | R16: 2 | S16: 0 | T16: 0 | U16: 0 | V16: 0 | W16: =(P16*$P$22+Q16*$Q$22+R16*$R$22+S16*$S$22+T16*$T$22+U16*$U$22+V16*$V$22)/$W$22 -> 2.25
A17: 14 | B17: TOTAL | D17: =SUM(D4:D16) -> 2059.954 | E17: =SUM(E4:E16) -> 8066.62 | F17: =SUM(F4:F16) -> 10126.574 | G17: =SUM(G4:G16) -> 7518.31 | H17: =SUM(H4:H16) -> 2598.044 | I17: =SUM(I4:I16) -> 100 | J17: =SUM(J4:J16) -> 100 | K17: =SUM(K4:K16) -> 85.798615 | L17: <<---- Target | O17: TOTAL | P17: =SUM(P4:P16) -> 100 | Q17: =SUM(Q4:Q16) -> 100 | R17: =SUM(R4:R16) -> 100 | S17: =SUM(S4:S16) -> 0 | T17: =SUM(T4:T16) -> 0 | U17: =SUM(U4:U16) -> 0 | V17: 0 | W17: =SUM(W4:W16) -> 100
B19: BILLET END CUT | D19: 0 | E19: =Recieving!R34 -> 87.73 | F19: =D19+E19 -> 87.73 | G19: ='Issue '!U35 -> 87.73 | H19: =F19-G19 -> 0 | J19: =(G19/$M$28)*100 -> 1.3568504
A20: 16 | B20: Slag Iron (Jam) | D20: 0 | E20: =Recieving!S34 -> 66.01 | F20: =(D20+E20) -> 66.01 | G20: ='Issue '!Z35 -> 66.01 | H20: =F20-G20 -> 0 | I20: =W20 -> 0 | J20: =(G20/$G$17)*100 -> 0.87798987 | K20: =J20*L20 -> 0 | O20: Salg Iron (Jam) | P20: 0 | Q20: 0 | R20: 0 | S20: 0 | T20: 0 | U20: 0 | V20: 0 | W20: =(P20*$P$22+Q20*$Q$22+R20*$R$22+S20*$S$22+T20*$T$22+U20*$U$22)/$W$22 -> 0
A21: 17 | B21: MILL SCALE | D21: 132.871 | E21: =Recieving!T34 -> 0 | F21: =(D21+E21) -> 132.871 | G21: ='Issue '!AA35 -> 44.5 | H21: =F21-G21 -> 88.371 | J21: =(G21/$M$28)*100 -> 0.68824625
A22: Power Consumption reports . | I22: Actual Yield---->>>> | L22: =C27/G17*100 -> 85.9995 | M22: =+K17-L22 -> -0.20088512 | O22: Days | P22: 4 | Q22: 7 | R22: 5 | S22: 0 | T22: 0 | U22: 0 | V22: 0 | W22: =SUM(P22:V22) -> 16
A23: Sl no | B23: Area | C23: Units (KW) | D23: Avg PF | E23: Per MT (KW) | F23: Target MT (KW) | G23: Diff | H23: Consumed MWH | I23: PP Available MWH | J23: Target PLF (13 MW) | K23: Actual PLF | L23: Target Prodn | M23: Avg. Prodn/day | O23: SCRAP SHEARING REPORTS | Q23: SL NO | R23: MODEL | T23: MT GREEN
A24: 1 | B24: Furnace | C24: ='Issue '!AB35 -> 4220464 | D24: 0.999 | E24: =C24/C27 -> 652.74574 | F24: =T32 -> 660.19833 | G24: =E24-F24 -> -7.45259 | H24: =((C24/$P$1/24)/1000)/D24 -> 11.001793 | I24: =Recieving!AD34 -> 12.91 | K24: =H24/I24*100 -> 85.219159 | O24: Total runing hours | P24: =Recieving!AB34 -> 13.208333 | R24: FURNACE CAPACITY | T24: 30
A25: 2 | B25: Auxiliary | C25: ='Issue '!AC35+'Issue '!AD35 -> 426431 | D25: 0.999 | E25: =(C25/$C$27) -> 65.952705 | F25: =W43 -> 65.929171 | G25: =E25-F25 -> 0.02353446 | H25: =((C25/$P$1/24)/1000)/D25 -> 1.111609 | I25: 0 | K25: =H25/I26*100 -> 8.6104493 | O25: Total scrap cutting (MT) | P25: =Recieving!AC34 -> 3170 | Q25: 1 | R25: SCRAP YIELD - % | T25: =L22 -> 85.9995
B26: Total | C26: =C24+C25 -> 4646895 | E26: =SUM(E24:E25) -> 718.69844 | F26: =SUM(F24:F25) -> 726.1275 | G26: =SUM(G24:G25) -> -7.4290555 | H26: =SUM(H24:H25) -> 12.113402 | I26: =SUM(I24:I25) -> 12.91 | J26: 90 | K26: =SUM(K24:K25) -> 93.829609 | L26: =T42 -> 393.37671 | M26: =C27/P1 -> 404.10681 | O26: Power consumption unit | P26: ='Issue '!AD35 -> 50899 | R26: RAW MATERIAL - | T26: as per sheet2
B27: Billet Production | C27: ='Issue '!T35 -> 6465.709 | O27: spc production mt /Hrs | P27: =P25/P24 -> 240 | R27: CARBON ON L.M | T27: 0.08 to 0.12
K28: Daily | L28: =+L26*W22 -> 6294.0273 | M28: =+M26*W22 -> 6465.709 | O28: spc.Power /MT | P28: =P26/P25 -> 16.056467 | Q28: 2 | R28: MEGATHERM UPT ON 100% | T28: 455
Q29: 3.A | R29: MEGATHERM UPT AS PER AVAILABLE YIELD | T29: =((T28*(2-T25/100))/(T25/100)) -> 603.14569
K30: Monthly | L30: =L26*31 -> 12194.678 | M30: =M26*31 -> 12527.311 | O30: SILICON MAG | Q30: 3.B | R30: ADDITIONAL POWER @1660 | T30: 24
K31: Diffrence | L31: =+L30-M30 -> -332.63332 | R31: ADDITIONAL PELLETS AND FINES | T31: =J5+J6 -> 33.052641
O32: Opening | P32: 52646 | Q32: 3.C | R32: TOTAL UNITS | T32: =T29+T30+T31 -> 660.19833
L33: =410*16 -> 6560 | O33: Received | P33: =Recieving!AE34 -> 104500 | Q33: 5 | R33: LINING LIFE | T33: 16
L34: =M28+L33 -> 13025.709 | O34: Issue | P34: =Recieving!AF34 -> 82600 | Q34: 6 | R34: POWER | T34: 12000
O35: Balance | P35: =+P32+P33-P34 -> 74546 | Q35: 7 | R35: LOAD FACTOR | T35: 0.9
O36: Average Per m/t | P36: =+P34/M28 -> 12.775088 | Q36: 8 | R36: MELT RATE | T36: =(T34*T35)/(T32-T31) -> 17.220879
O37: Bag Filter Dust | P37: ='Issue '!Y35 -> 8.37 | Q37: 9 | R37: TONNAGE AVERAGE | T37: 34
O38: Raw Slag | P38: ='Slag Crusher '!F34 -> 1404.78 | Q38: 10 | R38: HEAT TIME - MINS | T38: =T37*60/T36 -> 118.46085
O39: Mag Material Slag | P39: ='Slag Crusher '!H34 -> 157.63 | Q39: 11 | R39: LOSS OF TIME IN MIN ON A/C SLAG OFF 2 TIMES 6MIN, TEMP CHECKING 2 MIN, TAPPING TIME 3 MIN, BACK 1MIN, LINING INSPECTION 2 MINTILTING | T39: 6
O40: Mag Output % | P40: =P39/P38*100 -> 11.220974 | Q40: 12 | R40: TOTAL HEAT TIME | T40: =T39+T38 -> 124.46085
Q41: 13 | R41: HEATS PER DAY | T41: =24*60/T40 -> 11.569903
...

Sheet Sheet1
A1: Prod-If Q2 Buddget
A2: Month | B2: Buddget Amount | C2: Indent Amount | D2: Ballence buddget
A3: 46296 | B3: 14220318 | C3: =B3-D3 -> 4299279.9 | D3: 9921037.8
